Workbook

Sheet Drivers & Assumptons
A1: Category | B1: Item | C1: Value | D1: Notes / Units
A2: Model Timeline | B2: Model Start Year | C2: 2022 | D2: First year in model
A3: Model Timeline | B3: Model Start Date | C3: 44592 | D3: For monthly builds
A4: Model Timeline | B4: Forecast End Year | C4: 2032 | D4: Last year in projection
A5: USDC Metrics | B5: USDC Circulation Growth (Base) | C5: 0.08 | D5: YoY growth rate assumption: Historical growth: 2022 = 5.04%, 2023 = –44.69%, 2024 = 77.98%, 2025 (annualized) = 95.57%. Base case assumes normalized adoption rate between historical median (5%) and trimmed recovery (~37%).
A6: USDC Metrics | B6: Avg Float % of Circulation | C6: 1 | D6: Portion of circulation invested in reserves - Based on 3-year historical average (2022–2024) of 100.5%.
A7: USDC Metrics | B7: Daily Weighted-Average % of USDC on Platform | C7: -
A8: USDC Metrics | B8: Revenue Sharing Rate (on off platform USDC) | C8: -
A9: Circle Metrics | B9: Circle Platform % of Circulation | C9: 0.08
A10: Coinbase Metrics | B10: Coinbase Platform % of Circulation | C10: 0.24
A11: Outside Rate | B11: Outside Platforms % of Circulation | C11: 0.7
A12: Coinbase Metrics | B12: Coinbase Retained % | C12: 1
A13: Other Platorms | B13: Other Platforms Retained % | C13: 1
A14: Reserve Yields | B14: 3M T-Bill Yield (Base) | C14: 0.0497 | D14: Used for Treasuries portion - Average of Circle provided quarterly rates
A15: Reserve Yields | B15: SOFR Rate (Base) | C15: 0.0515 | D15: Used for repo portion - Average of Circle provided quarterly rates
A16: Reserve Yields | B16: Cash Yield (Base) | C16: 0.10% | D16: Used for cash portion
A17: Rates | B17: Forecasted Weighted Yield Rate | C17: 0.041 | D17: Short-term rates will gradually decline in H2 2025 (based on macro expectations for rate cuts) - within the 3.75 - 3.97% range
A18: Rates | B18: Effective Tax Rate | C18: 0.21 | D18: Based on FY2024 effective tax rate per Circle disclosure; 2025 rate excluded due to IPO-related discrete items. 35% historical rate -> phased down to avoid understating profitability
A19: Transaction Assumptions | B19: Transaction Volume Growth (Base) | C19: 0.12 | D19: YoY growth - Base set via weighted geometric mean of YoY factors: 2023 (w=0.20), 2024 (w=0.40), 2025 annualized (w=0.40). Result ≈ 11.24%; rounded to 12%. 2025 uses H1×2.
A20: Transaction Assumptions | B20: Take Rate | C20: 0.0002 | D20: % of transaction value captured as fee revenue (on/off-ramp fee take rate)
A21: Expense Drivers | B21: Partner Payout Rate (on Reserve Income) | C21: 0.5 | D21: Paid to partners from float income
A22: Expense Drivers | B22: Cost of Revenue % of Total Revenue | C22: 0.61019 | D22: Payment processing & network costs
A23: Expense Drivers | B23: Compensation Expense % of Total Revenue | C23: 0.19065 | D23: Compensation Expenses - Internal costs
A24: Expense Drivers | B24: Sales & Marketing % of Revenue | C24: 0.01 | D24: Opex driver
A25: Expense Drivers | B25: R&D % of Total Revenue | C25: 0.015 | D25: Opex driver
A26: Expense Drivers | B26: G&A % of Total Revenue | C26: 0.06 | D26: Opex driver
A27: Expense Drivers | B27: D&A % of Total Revenue | C27: 0.0226 | D27: Opex driver
A28: Expense Drivers | B28: IT & Infrastructure % Total Revenue | C28: 0.01329 | D28: Opex driver
... A31: Scenario Toggles | B31: Take Rate Delta (%) | C31: 0 | D31: Adjusts transaction fees
A33: Cash & CE | B33: Corporate Supply | C33: 0.15
A34: Cash & CE | B34: USDC for holders | C34: 0.08
A35: DSO | B35: AR % of Total Revenue | C35: =AVERAGE(('Balance Sheet'!D10/'P&L'!E2),('Balance Sheet'!C10/'P&L'!D2)) -> 0.0072574484
A36: AP | B36: AP % Total Costs | C36: =AVERAGE(('Balance Sheet'!B29/('Expense Build'!C6+'Expense Build'!C18)),('Balance Sheet'!C29/('Expense Build'!D6+'Expense Build'!D18)),('Balance Sheet'!D29/('Expense Build'!E6+'Expense Build'!E18))) -> 0.19983327
A37: AP | B37: AP % of Opex | C37: =AVERAGE(('Balance Sheet'!D29/'P&L'!E22),('Balance Sheet'!C29/'P&L'!D22),('Balance Sheet'!B29/'P&L'!C22)) -> 0.49872962
A38: Prepaid Exp & Other Current Exp | B38: % of Opex | C38: =AVERAGE(('Balance Sheet'!B12/'P&L'!C22),('Balance Sheet'!C12/'P&L'!D22),('Balance Sheet'!D12/'P&L'!E22)) -> 0.3359993
A39: Fixed Assets | B39: % of Opex | C39: =AVERAGE(('Balance Sheet'!D17/'P&L'!E22),('Balance Sheet'!C17/'P&L'!D22),('Balance Sheet'!B17/'P&L'!C22)) -> 0.02569238
A40: Fixed Assets 2025E | B40: Fixed Percentage assumed at 20% | C40: 0.2
A41: Other Assets/Liabilities | B41: % of Total Revenue
A42: Deferred Revenue | B42: % of Transaction Revenue | C42: =AVERAGE(('Balance Sheet'!B28/'P&L'!C2),('Balance Sheet'!C28/'P&L'!D2),('Balance Sheet'!D28/'P&L'!E2)) -> 0.0055300039
A44: Stock Compensation | B44: % of Total Compensation Expense | C44: =AVERAGE(('Cash Flow Statement'!B17/'Expense Build'!B9),('Cash Flow Statement'!C17/'Expense Build'!C9),('Cash Flow Statement'!D17/'Expense Build'!D9)) -> 0.29345754
...

Sheet Revenue Build
A1: (in millions) | B1: ='Drivers & Assumptons'!C2 & "A" -> 2022A | C1: =LEFT(B1,4) + 1 & IF(LEFT(B1,4) + 1 <= 2024, "A", "E") -> 2023A | D1: =LEFT(C1,4) + 1 & IF(LEFT(C1,4) + 1 <= 2024, "A", "E") -> 2024A | E1: 2025 6M Actual | F1: =LEFT(D1,4) + 1 & IF(LEFT(D1,4) + 1 <= 2024, "A", "E") -> 2025E | G1: =LEFT(F1,4) + 1 & IF(LEFT(F1,4) + 1 <= 2024, "A", "E") -> 2026E | H1: =LEFT(G1,4) + 1 & IF(LEFT(G1,4) + 1 <= 2024, "A", "E") -> 2027E | I1: =LEFT(H1,4) + 1 & IF(LEFT(H1,4) + 1 <= 2024, "A", "E") -> 2028E | J1: =LEFT(I1,4) + 1 & IF(LEFT(I1,4) + 1 <= 2024, "A", "E") -> 2029E | K1: =LEFT(J1,4) + 1 & IF(LEFT(J1,4) + 1 <= 2024, "A", "E") -> 2030E | L1: =LEFT(K1,4) + 1 & IF(LEFT(K1,4) + 1 <= 2024, "A", "E") -> 2031E | M1: =LEFT(L1,4) + 1 & IF(LEFT(L1,4) + 1 <= 2024, "A", "E") -> 2032E
A2: USDC Circulation (Base, in millions) BOY | B2: 42416 | C2: 44554 | D2: 24412 | E2: 43857 | F2: =E2 -> 43857 | G2: =F3 -> 63739.123 | H2: =G3 -> 68838.253 | I2: =H3 -> 74345.313 | J2: =I3 -> 80292.939 | K2: =J3 -> 86716.374 | L2: =K3 -> 93653.683 | M2: =L3 -> 101145.98
A3: USDC Circulation (Base, in millions) EOY | B3: 44554 | C3: 24412 | D3: 43857 | E3: 61333 | F3: =E3*(1+'Drivers & Assumptons'!C5)^0.5 -> 63739.123 | G3: =G2*(1+'Drivers & Assumptons'!$C$5) -> 68838.253 | H3: =H2*(1+'Drivers & Assumptons'!$C$5) -> 74345.313 | I3: =I2*(1+'Drivers & Assumptons'!$C$5) -> 80292.939 | J3: =J2*(1+'Drivers & Assumptons'!$C$5) -> 86716.374 | K3: =K2*(1+'Drivers & Assumptons'!$C$5) -> 93653.683 | L3: =L2*(1+'Drivers & Assumptons'!$C$5) -> 101145.98 | M3: =M2*(1+'Drivers & Assumptons'!$C$5) -> 109237.66
A4: Growth EOY % | C4: =(C3-B3)/B3 -> -0.45208062 | D4: =(D3-C3)/C3 -> 0.79653449 | E4: =(E3-D3)/D3 -> 0.39847687 | F4: =(F3-E3)/E3 -> 0.039230485 | G4: =(G3-F3)/F3 -> 0.08 | H4: =(H3-G3)/G3 -> 0.08 | I4: =(I3-H3)/H3 -> 0.08 | J4: =(J3-I3)/I3 -> 0.08 | ... M4: =(M3-L3)/L3 -> 0.08
A5: USDC Circulation (Base, in millions) Average | B5: 49861 | C5: 30467 | D5: 33342 | E5: 57574 | F5: =((E5*6)+((((E3+F3)/2)*6))) / 12 -> 60055.031 | G5: =(G2+G3)/2 -> 66288.688 | H5: =(H2+H3)/2 -> 71591.783 | I5: =(I2+I3)/2 -> 77319.126 | J5: =(J2+J3)/2 -> 83504.656 | K5: =(K2+K3)/2 -> 90185.029 | L5: =(L2+L3)/2 -> 97399.831 | M5: =(M2+M3)/2 -> 105191.82
A6: Avg Float % of Circulation | B6: =[1]Calculations!$J$2 -> 0.99926934 | C6: =[1]Calculations!$J$3 -> 1.0208429 | D6: =[1]Calculations!$J$4 -> 0.99501889 | E6: =[1]Calculations!$J$5 -> 0.98424448 | F6: =((E6*E5)+(F5*'Drivers & Assumptons'!C6))/('Revenue Build'!E5+'Revenue Build'!F5) -> 0.9922884 | G6: =AVERAGE($B$6:$F$6) -> 0.99833281 | H6: =AVERAGE($B$6:$F$6) -> 0.99833281 | I6: =AVERAGE($B$6:$F$6) -> 0.99833281 | J6: =AVERAGE($B$6:$F$6) -> 0.99833281 | K6: =AVERAGE($B$6:$F$6) -> 0.99833281 | L6: =AVERAGE($B$6:$F$6) -> 0.99833281 | M6: =AVERAGE($B$6:$F$6) -> 0.99833281
A7: Implied Float % of Circulation | B7: =B21/(B5*B8) -> 0.98391528 | C7: =C21/(C5*C8) -> 0.99906212 | D7: =D21/(D5*D8) -> 0.99639134 | E7: =E21/(E5*E8) -> 0.49302388 | F7: =F21/(F5*F8) -> 0.97361981 | G7: =G21/(G5*G8) -> 0.99833281 | H7: =H21/(H5*H8) -> 0.99833281 | I7: =I21/(I5*I8) -> 0.99833281 | ... M7: =M21/(M5*M8) -> 0.99833281
A8: Reserve Return Rate | B8: 0.015 | C8: 0.047 | D8: 0.05 | E8: 0.042 | F8: =((E8*6)+('Drivers & Assumptons'!C17*6))/12 -> 0.0415 | G8: =[1]Metrics!$D$9 -> 0.033 | H8: =[1]Metrics!$D$10 -> 0.0295 | I8: =[1]Metrics!$D$11 -> 0.0275 | J8: =[1]Metrics!$D$12 -> 0.0255 | K8: =[1]Metrics!$D$13 -> 0.025 | L8: =[1]Metrics!$D$14 -> 0.025 | M8: =[1]Metrics!$D$15 -> 0.026
A9: Base Gross Reserve Income (Circle Retains 100%) | B9: =B5*B7*B8 -> 735.885 | C9: =C5*C7*C8 -> 1430.606 | D9: =D5*D7*D8 -> 1661.084 | E9: =E5*E7*E8 -> 1192.185 | F9: =F5*F7*F8 -> 2426.5369 | G9: =G5*G7*G8 -> 2183.8797 | H9: =H5*H7*H8 -> 2108.4366 | I9: =I5*I7*I8 -> 2122.731 | ... M9: =M5*M7*M8 -> 2730.4275
A10: Circle % of Float | B10: 0.01 | C10: 0.02 | D10: 0.05 | E10: 0.07 | F10: ='Drivers & Assumptons'!C9 -> 0.08 | G10: =F10+0.01 -> 0.09 | H10: =G10+0.01 -> 0.1 | I10: =H10+0.01 -> 0.11 | J10: =I10+0.01 -> 0.12 | K10: =J10+0.01 -> 0.13 | L10: =K10+0.01 -> 0.14 | M10: =L10+0.01 -> 0.15
A11: Circle Gross Reserve Income | B11: =B9*B10 -> 7.35885 | C11: =C9*C10 -> 28.61212 | D11: =D9*D10 -> 83.0542 | E11: =E9*E10 -> 83.45295 | F11: =F9*F10 -> 194.12295 | G11: =G9*G10 -> 196.54917 | H11: =H9*H10 -> 210.84366 | I11: =I9*I10 -> 233.50042 | ... M11: =M9*M10 -> 409.56412
A12: Coinbase % of Float | B12: 0.05 | C12: 0.12 | D12: 0.2 | E12: 0.23 | F12: ='Drivers & Assumptons'!C10 -> 0.24 | G12: =F12+0.01 -> 0.25 | H12: =G12 -> 0.25 | I12: =H12 -> 0.25 | J12: =I12+0.01 -> 0.26 | K12: =J12 -> 0.26 | L12: =K12 -> 0.26 | M12: =L12+0.01 -> 0.27
A13: Coinbase Gross Reserve Income | B13: =B9*B12 -> 36.79425 | C13: =C9*C12 -> 171.67272 | D13: =D9*D12 -> 332.2168 | E13: =E9*E12 -> 274.20255 | F13: =F9*F12 -> 582.36885 | G13: =G9*G12 -> 545.96992 | H13: =H9*H12 -> 527.10914 | I13: =I9*I12 -> 530.68276 | ... M13: =M9*M12 -> 737.21542
A14: Coinbase Retained % | B14: ='Drivers & Assumptons'!$C$12 -> 1 | C14: ='Drivers & Assumptons'!$C$12 -> 1 | D14: ='Drivers & Assumptons'!$C$12 -> 1 | E14: ='Drivers & Assumptons'!$C$12 -> 1 | F14: ='Drivers & Assumptons'!$C$12 -> 1 | G14: ='Drivers & Assumptons'!$C$12 -> 1 | H14: ='Drivers & Assumptons'!$C$12 -> 1 | I14: ='Drivers & Assumptons'!$C$12 -> 1 | ... M14: ='Drivers & Assumptons'!$C$12 -> 1
A15: Coinbase Net Reserve Income | B15: =B13*B14 -> 36.79425 | C15: =C13*C14 -> 171.67272 | D15: =D13*D14 -> 332.2168 | E15: =E13*E14 -> 274.20255 | F15: =F13*F14 -> 582.36885 | G15: =G13*G14 -> 545.96992 | H15: =H13*H14 -> 527.10914 | I15: =I13*I14 -> 530.68276 | ... M15: =M13*M14 -> 737.21542
A16: Outside % of Float | B16: 0.94 | C16: 0.86 | D16: 0.75 | E16: 0.7 | F16: =1-F10-F12 -> 0.68 | G16: =1-G10-G12 -> 0.66 | H16: =1-H10-H12 -> 0.65 | I16: =1-I10-I12 -> 0.64 | J16: =1-J10-J12 -> 0.62 | K16: =1-K10-K12 -> 0.61 | L16: =1-L10-L12 -> 0.6 | M16: =1-M10-M12 -> 0.58
A17: Outside Gross Reserve Income | B17: =B9*B16 -> 691.7319 | C17: =C9*C16 -> 1230.3212 | D17: =D9*D16 -> 1245.813 | E17: =E9*E16 -> 834.5295 | F17: =F9*F16 -> 1650.0451 | G17: =G9*G16 -> 1441.3606 | H17: =H9*H16 -> 1370.4838 | I17: =I9*I16 -> 1358.5479 | ... M17: =M9*M16 -> 1583.6479
A18: Outside Retained % | B18: ='Drivers & Assumptons'!$C$13 -> 1 | C18: ='Drivers & Assumptons'!$C$13 -> 1 | D18: ='Drivers & Assumptons'!$C$13 -> 1 | E18: ='Drivers & Assumptons'!$C$13 -> 1 | F18: ='Drivers & Assumptons'!$C$13 -> 1 | G18: ='Drivers & Assumptons'!$C$13 -> 1 | H18: ='Drivers & Assumptons'!$C$13 -> 1 | I18: ='Drivers & Assumptons'!$C$13 -> 1 | ... M18: ='Drivers & Assumptons'!$C$13 -> 1
A19: Outside Net Reserve Income | B19: =B17*B18 -> 691.7319 | C19: =C17*C18 -> 1230.3212 | D19: =D17*D18 -> 1245.813 | E19: =E17*E18 -> 834.5295 | F19: =F17*F18 -> 1650.0451 | G19: =G17*G18 -> 1441.3606 | H19: =H17*H18 -> 1370.4838 | I19: =I17*I18 -> 1358.5479 | ... M19: =M17*M18 -> 1583.6479
A20: Implied Total Reserve Income | B20: =B15+B19+B11 -> 735.885 | C20: =C15+C19+C11 -> 1430.606 | D20: =D15+D19+D11 -> 1661.084 | E20: =E15+E19+E11 -> 1192.185 | F20: =F15+F19+F11 -> 2426.5369 | G20: =G15+G19+G11 -> 2183.8797 | H20: =H15+H19+H11 -> 2108.4366 | I20: =I15+I19+I11 -> 2122.731 | ... M20: =M15+M19+M11 -> 2730.4275
A21: Total Reserve Income | B21: =735885 / 1000 -> 735.885 | C21: =1430606/1000 -> 1430.606 | D21: =1661084/1000 -> 1661.084 | E21: =1192185/1000 -> 1192.185 | F21: =((E5*E6*E8)*(6/12)) + ((F5*F6*F8)*(6/12)) -> 2426.5369 | G21: =G5*G6*G8 -> 2183.8797 | H21: =H5*H6*H8 -> 2108.4366 | I21: =I5*I6*I8 -> 2122.731 | J21: =J5*J6*J8 -> 2125.8187 | K21: =K5*K6*K8 -> 2250.8668 | L21: =L5*L6*L8 -> 2430.9362 | M21: =M5*M6*M8 -> 2730.4275
A22: Total Reserve Income Check | B22: =B20-B21 -> 0 | C22: =C20-C21 -> 0 | D22: =D20-D21 -> 0 | E22: =E20-E21 -> 0 | F22: =F20-F21 -> 0 | G22: =G20-G21 -> 0 | H22: =H20-H21 -> 0 | I22: =I20-I21 -> 0 | ... M22: =M20-M21 -> 0
A24: Transaction Volume (in millions) | B24: =[1]Metrics!$B$20 -> 333080 | C24: =[1]Metrics!$B$21 -> 211808 | D24: =[1]Metrics!$B$23 -> 263239 | E24: =[1]Metrics!$B$24 -> 173316 | F24: =[1]Metrics!$B$26 -> 346632 | G24: =F24*(1+'Drivers & Assumptons'!$C$19) -> 388227.84 | H24: =G24*(1+'Drivers & Assumptons'!$C$19) -> 434815.18 | I24: =H24*(1+'Drivers & Assumptons'!$C$19) -> 486993 | J24: =I24*(1+'Drivers & Assumptons'!$C$19) -> 545432.16 | K24: =J24*(1+'Drivers & Assumptons'!$C$19) -> 610884.02 | L24: =K24*(1+'Drivers & Assumptons'!$C$19) -> 684190.11 | M24: =L24*(1+'Drivers & Assumptons'!$C$19) -> 766292.92
A25: Take Rate | B25: =B26/B24 -> 0.00010858352 | C25: =C26/C24 -> 9.3764164e-05 | D25: =D26/D24 -> 5.762444e-05 | E25: =E26/E24 -> 0.00025656027 | F25: ='Drivers & Assumptons'!$C$20 -> 0.0002 | G25: ='Drivers & Assumptons'!$C$20 -> 0.0002 | H25: ='Drivers & Assumptons'!$C$20 -> 0.0002 | I25: ='Drivers & Assumptons'!$C$20 -> 0.0002 | J25: ='Drivers & Assumptons'!$C$20 -> 0.0002 | K25: ='Drivers & Assumptons'!$C$20 -> 0.0002 | L25: ='Drivers & Assumptons'!$C$20 -> 0.0002 | M25: ='Drivers & Assumptons'!$C$20 -> 0.0002
A26: Transaction & Other Revenue | B26: =36167 / 1000 -> 36.167 | C26: =19860/1000 -> 19.86 | D26: =15169/1000 -> 15.169 | E26: =44466/1000 -> 44.466 | F26: =F25*F24 -> 69.3264 | G26: =G25*G24 -> 77.645568 | H26: =H25*H24 -> 86.963036 | I26: =I25*I24 -> 97.3986 | J26: =J25*J24 -> 109.08643 | K26: =K25*K24 -> 122.1768 | L26: =L25*L24 -> 136.83802 | M26: =M25*M24 -> 153.25858
A28: Implied Total Revenue | B28: =B26+B21 -> 772.052 | C28: =C26+C21 -> 1450.466 | D28: =D26+D21 -> 1676.253 | E28: =E26+E21 -> 1236.651 | F28: =F26+F20 -> 2495.8633 | G28: =G20+G26 -> 2261.5252 | H28: =H20+H26 -> 2195.3996 | I28: =I20+I26 -> 2220.1296 | J28: =J20+J26 -> 2234.9051 | K28: =K20+K26 -> 2373.0436 | L28: =L20+L26 -> 2567.7742 | M28: =M20+M26 -> 2883.6861
A29: Total Revenue | B29: =772052/1000 -> 772.052 | C29: =1450466/1000 -> 1450.466 | D29: =1676253/1000 -> 1676.253 | E29: =1236651/1000 -> 1236.651 | F29: =F26+F21 -> 2495.8633 | G29: =G21+G26 -> 2261.5252 | H29: =H21+H26 -> 2195.3996 | I29: =I21+I26 -> 2220.1296 | J29: =J21+J26 -> 2234.9051 | K29: =K21+K26 -> 2373.0436 | L29: =L21+L26 -> 2567.7742 | M29: =M21+M26 -> 2883.6861

Sheet Expense Build
A1: (in millions) | B1: ='Drivers & Assumptons'!C2 & "A" -> 2022A | C1: =LEFT(B1,4) + 1 & IF(LEFT(B1,4) + 1 <= 2024, "A", "E") -> 2023A | D1: =LEFT(C1,4) + 1 & IF(LEFT(C1,4) + 1 <= 2024, "A", "E") -> 2024A | E1: 2025 6M Actual | F1: =LEFT(D1,4) + 1 & IF(LEFT(D1,4) + 1 <= 2024, "A", "E") -> 2025E | G1: =LEFT(F1,4) + 1 & IF(LEFT(F1,4) + 1 <= 2024, "A", "E") -> 2026E | H1: =LEFT(G1,4) + 1 & IF(LEFT(G1,4) + 1 <= 2024, "A", "E") -> 2027E | I1: =LEFT(H1,4) + 1 & IF(LEFT(H1,4) + 1 <= 2024, "A", "E") -> 2028E | J1: =LEFT(I1,4) + 1 & IF(LEFT(I1,4) + 1 <= 2024, "A", "E") -> 2029E | K1: =LEFT(J1,4) + 1 & IF(LEFT(J1,4) + 1 <= 2024, "A", "E") -> 2030E | L1: =LEFT(K1,4) + 1 & IF(LEFT(K1,4) + 1 <= 2024, "A", "E") -> 2031E | M1: =LEFT(L1,4) + 1 & IF(LEFT(L1,4) + 1 <= 2024, "A", "E") -> 2032E
A2: Total Revenue | B2: ='Revenue Build'!B29 -> 772.052 | C2: ='Revenue Build'!C29 -> 1450.466 | D2: ='Revenue Build'!D29 -> 1676.253 | E2: ='Revenue Build'!E29 -> 1236.651 | F2: ='Revenue Build'!F29 -> 2495.8633 | G2: ='Revenue Build'!G29 -> 2261.5252 | H2: ='Revenue Build'!H29 -> 2195.3996 | I2: ='Revenue Build'!I29 -> 2220.1296 | ... M2: ='Revenue Build'!M29 -> 2883.6861
A3: Distribution & Transaction Costs | B3: =286953/1000 -> 286.953 | C3: =719806/1000 -> 719.806 | D3: =1010811/1000 -> 1010.811 | E3: =753784/1000 -> 753.784 | F3: =F2*(E3/E2) -> 1521.3199 | G3: =G2*(F3/F2) -> 1378.4823 | H3: =H2*(G3/G2) -> 1338.1763 | I3: =I2*(H3/H2) -> 1353.2502 | J3: =J2*(I3/I2) -> 1362.2564 | K3: =K2*(J3/J2) -> 1446.4568 | L3: =L2*(K3/K2) -> 1565.1522 | M3: =M2*(L3/L2) -> 1757.7121
A4: Other Costs | B4: =22401/1000 -> 22.401 | C4: =7918/1000 -> 7.918 | D4: =6553/1000 -> 6.553 | E4: =805/1000 -> 0.805 | F4: =F2*(E4/E2) -> 1.6246863 | G4: =G2*(F4/F2) -> 1.4721436 | H4: =H2*(G4/G2) -> 1.429099 | I4: =I2*(H4/H2) -> 1.445197 | J4: =J2*(I4/I2) -> 1.4548151 | K4: =K2*(J4/J2) -> 1.5447366 | L4: =L2*(K4/K2) -> 1.6714968 | M4: =M2*(L4/L2) -> 1.8771402
A5: Implied Total Distribution, Transaction, and Other Costs | B5: =B2*[1]Metrics!$D$49 -> 309.354 | C5: =C2*[1]Metrics!$D$50 -> 727.724 | D5: =D2*[1]Metrics!$D$51 -> 1017.364 | E5: =E2*[1]Metrics!$D$52 -> 754.589 | F5: =F2*'Drivers & Assumptons'!$C$22 -> 1522.9508 | G5: =G2*'Drivers & Assumptons'!$C$22 -> 1379.9601 | H5: =H2*'Drivers & Assumptons'!$C$22 -> 1339.6109 | I5: =I2*'Drivers & Assumptons'!$C$22 -> 1354.7009 | J5: =J2*'Drivers & Assumptons'!$C$22 -> 1363.7167 | K5: =K2*'Drivers & Assumptons'!$C$22 -> 1448.0075 | L5: =L2*'Drivers & Assumptons'!$C$22 -> 1566.8301 | M5: =M2*'Drivers & Assumptons'!$C$22 -> 1759.5964
A6: Total Distribution, Transaction, and Other Costs | B6: =SUM(B3:B4) -> 309.354 | C6: =SUM(C3:C4) -> 727.724 | D6: =SUM(D3:D4) -> 1017.364 | E6: =SUM(E3:E4) -> 754.589 | F6: =SUM(F3:F4) -> 1522.9446 | G6: =SUM(G3:G4) -> 1379.9545 | H6: =SUM(H3:H4) -> 1339.6054 | I6: =SUM(I3:I4) -> 1354.6954 | ... M6: =SUM(M3:M4) -> 1759.5892
A8: Operating Expenses
A9: Compensation Expenses | B9: =212961/1000 -> 212.961 | C9: =296055/1000 -> 296.055 | D9: =263410/1000 -> 263.41 | E9: =579012/1000 -> 579.012 | F9: =F2*'Drivers & Assumptons'!$C$23 -> 475.83633 | G9: =G2*'Drivers & Assumptons'!$C$23 -> 431.15979 | H9: =H2*'Drivers & Assumptons'!$C$23 -> 418.55293 | I9: =I2*'Drivers & Assumptons'!$C$23 -> 423.26772 | J9: =J2*'Drivers & Assumptons'!$C$23 -> 426.08466 | K9: =K2*'Drivers & Assumptons'!$C$23 -> 452.42077 | L9: =L2*'Drivers & Assumptons'!$C$23 -> 489.54615 | M9: =M2*'Drivers & Assumptons'!$C$23 -> 549.77475
A10: G & A Expenses | B10: =82272/1000 -> 82.272 | C10: =100128/1000 -> 100.128 | D10: =137283/1000 -> 137.283 | E10: =73824/1000 -> 73.824 | F10: =F2*'Drivers & Assumptons'!$C$26 -> 149.7518 | G10: =G2*'Drivers & Assumptons'!$C$26 -> 135.69151 | H10: =H2*'Drivers & Assumptons'!$C$26 -> 131.72398 | I10: =I2*'Drivers & Assumptons'!$C$26 -> 133.20778 | J10: =J2*'Drivers & Assumptons'!$C$26 -> 134.09431 | K10: =K2*'Drivers & Assumptons'!$C$26 -> 142.38262 | L10: =L2*'Drivers & Assumptons'!$C$26 -> 154.06645 | M10: =M2*'Drivers & Assumptons'!$C$26 -> 173.02116
A11: Depreciation & Amoritization Expenses | B11: =13277/1000 -> 13.277 | C11: =34887/1000 -> 34.887 | D11: =50854/1000 -> 50.854 | E11: =28089/1000 -> 28.089 | F11: =F2*'Drivers & Assumptons'!$C$27 -> 56.40651 | G11: =G2*'Drivers & Assumptons'!$C$27 -> 51.110471 | H11: =H2*'Drivers & Assumptons'!$C$27 -> 49.616031 | I11: =I2*'Drivers & Assumptons'!$C$27 -> 50.17493 | J11: =J2*'Drivers & Assumptons'!$C$27 -> 50.508855 | K11: =K2*'Drivers & Assumptons'!$C$27 -> 53.630786 | L11: =L2*'Drivers & Assumptons'!$C$27 -> 58.031696 | M11: =M2*'Drivers & Assumptons'!$C$27 -> 65.171305
A12: IT Infrastructure Costs | B12: =11835/1000 -> 11.835 | C12: =20722/1000 -> 20.722 | D12: =27109/1000 -> 27.109 | E12: =16432/1000 -> 16.432 | F12: =F2*'Drivers & Assumptons'!$C$28 -> 33.170023 | G12: =G2*'Drivers & Assumptons'!$C$28 -> 30.055671 | H12: =H2*'Drivers & Assumptons'!$C$28 -> 29.176861 | I12: =I2*'Drivers & Assumptons'!$C$28 -> 29.505523 | J12: =J2*'Drivers & Assumptons'!$C$28 -> 29.701889 | K12: =K2*'Drivers & Assumptons'!$C$28 -> 31.53775 | L12: =L2*'Drivers & Assumptons'!$C$28 -> 34.125719 | M12: =M2*'Drivers & Assumptons'!$C$28 -> 38.324188
A13: Marketing Expenses | B13: =78839/1000 -> 78.839 | C13: =36544/1000 -> 36.544 | D13: =17326/1000 -> 17.326 | E13: =11770/1000 -> 11.77 | F13: =F2*'Drivers & Assumptons'!$C$24 -> 24.958633 | G13: =G2*'Drivers & Assumptons'!$C$24 -> 22.615252 | H13: =H2*'Drivers & Assumptons'!$C$24 -> 21.953996 | I13: =I2*'Drivers & Assumptons'!$C$24 -> 22.201296 | J13: =J2*'Drivers & Assumptons'!$C$24 -> 22.349051 | K13: =K2*'Drivers & Assumptons'!$C$24 -> 23.730436 | L13: =L2*'Drivers & Assumptons'!$C$24 -> 25.677742 | M13: =M2*'Drivers & Assumptons'!$C$24 -> 28.836861
A14: Digital Assets (Gains) Losses and impairment | B14: =57436/1000 -> 57.436 | C14: =-13488/1000 -> -13.488 | D14: =-4251/1000 -> -4.251 | E14: =5577/1000 -> 5.577 | F14: =($B$14+$C$14+$D$14+$E$14)/4 -> 11.3185 | G14: =($B$14+$C$14+$D$14+$E$14)/4 -> 11.3185 | H14: =($B$14+$C$14+$D$14+$E$14)/4 -> 11.3185 | I14: =($B$14+$C$14+$D$14+$E$14)/4 -> 11.3185 | J14: =($B$14+$C$14+$D$14+$E$14)/4 -> 11.3185 | K14: =($B$14+$C$14+$D$14+$E$14)/4 -> 11.3185 | L14: =($B$14+$C$14+$D$14+$E$14)/4 -> 11.3185 | M14: =($B$14+$C$14+$D$14+$E$14)/4 -> 11.3185
A15: Gain on sale of intangible assets | B15: 0 | C15: =-21634/1000 -> -21.634 | D15: 0 | E15: 0 | F15: 0 | G15: 0 | H15: 0 | I15: 0 | J15: 0 | K15: 0 | L15: 0 | M15: 0
A16: Merger Termination Expenses | B16: =44194/1000 -> 44.194 | C16: 0 | D16: 0 | E16: 0 | F16: 0 | G16: 0 | H16: 0 | I16: 0 | J16: 0 | K16: 0 | L16: 0 | M16: 0
A17: Implied Total Operating Expenses | B17: =SUM(B9:B16) -> 500.814 | C17: =SUM(C9:C16) -> 453.214 | D17: =SUM(D9:D16) -> 491.731 | E17: =SUM(E9:E16) -> 714.704 | F17: =SUM(F9:F16) -> 751.44179 | G17: =SUM(G9:G16) -> 681.9512 | H17: =SUM(H9:H16) -> 662.3423 | I17: =SUM(I9:I16) -> 669.67575 | ... M17: =SUM(M9:M16) -> 866.44677
A18: Total Operating Expenses | B18: =500814/1000 -> 500.814 | C18: =453214/1000 -> 453.214 | D18: =491731/1000 -> 491.731 | E18: =714704/1000 -> 714.704 | F18: =SUM(F9:F16) -> 751.44179 | G18: =SUM(G9:G16) -> 681.9512 | H18: =SUM(H9:H16) -> 662.3423 | I18: =SUM(I9:I16) -> 669.67575 | J18: =SUM(J9:J16) -> 674.05726 | K18: =SUM(K9:K16) -> 715.02085 | L18: =SUM(L9:L16) -> 772.76625 | M18: =SUM(M9:M16) -> 866.44677

Sheet P&L
A1: (in millions) | B1: ='Drivers & Assumptons'!C2 & "A" -> 2022A | C1: =LEFT(B1,4) + 1 & IF(LEFT(B1,4) + 1 <= 2024, "A", "E") -> 2023A | D1: =LEFT(C1,4) + 1 & IF(LEFT(C1,4) + 1 <= 2024, "A", "E") -> 2024A | E1: 2025 6M Actual | F1: =LEFT(D1,4) + 1 & IF(LEFT(D1,4) + 1 <= 2024, "A", "E") -> 2025E | G1: =LEFT(F1,4) + 1 & IF(LEFT(F1,4) + 1 <= 2024, "A", "E") -> 2026E | H1: =LEFT(G1,4) + 1 & IF(LEFT(G1,4) + 1 <= 2024, "A", "E") -> 2027E | I1: =LEFT(H1,4) + 1 & IF(LEFT(H1,4) + 1 <= 2024, "A", "E") -> 2028E | J1: =LEFT(I1,4) + 1 & IF(LEFT(I1,4) + 1 <= 2024, "A", "E") -> 2029E | K1: =LEFT(J1,4) + 1 & IF(LEFT(J1,4) + 1 <= 2024, "A", "E") -> 2030E | L1: =LEFT(K1,4) + 1 & IF(LEFT(K1,4) + 1 <= 2024, "A", "E") -> 2031E | M1: =LEFT(L1,4) + 1 & IF(LEFT(L1,4) + 1 <= 2024, "A", "E") -> 2032E
A2: Total Revenue | B2: ='Revenue Build'!B29 -> 772.052 | C2: ='Revenue Build'!C29 -> 1450.466 | D2: ='Revenue Build'!D29 -> 1676.253 | E2: ='Revenue Build'!E29 -> 1236.651 | F2: ='Revenue Build'!F29 -> 2495.8633 | G2: ='Revenue Build'!G29 -> 2261.5252 | H2: ='Revenue Build'!H29 -> 2195.3996 | I2: ='Revenue Build'!I29 -> 2220.1296 | ... M2: ='Revenue Build'!M29 -> 2883.6861
A4: Cost of Revenue
A5: Distribution & Transaction Costs | B5: ='Expense Build'!B3 -> 286.953 | C5: ='Expense Build'!C3 -> 719.806 | D5: ='Expense Build'!D3 -> 1010.811 | E5: ='Expense Build'!E3 -> 753.784 | F5: ='Expense Build'!F3 -> 1521.3199 | G5: ='Expense Build'!G3 -> 1378.4823 | H5: ='Expense Build'!H3 -> 1338.1763 | I5: ='Expense Build'!I3 -> 1353.2502 | ... M5: ='Expense Build'!M3 -> 1757.7121
A6: Other Costs | B6: ='Expense Build'!B4 -> 22.401 | C6: ='Expense Build'!C4 -> 7.918 | D6: ='Expense Build'!D4 -> 6.553 | E6: ='Expense Build'!E4 -> 0.805 | F6: ='Expense Build'!F4 -> 1.6246863 | G6: ='Expense Build'!G4 -> 1.4721436 | H6: ='Expense Build'!H4 -> 1.429099 | I6: ='Expense Build'!I4 -> 1.445197 | ... M6: ='Expense Build'!M4 -> 1.8771402
A7: Total Costs of Revenue | B7: ='Expense Build'!B6 -> 309.354 | C7: ='Expense Build'!C6 -> 727.724 | D7: ='Expense Build'!D6 -> 1017.364 | E7: ='Expense Build'!E6 -> 754.589 | F7: ='Expense Build'!F6 -> 1522.9446 | G7: ='Expense Build'!G6 -> 1379.9545 | H7: ='Expense Build'!H6 -> 1339.6054 | I7: ='Expense Build'!I6 -> 1354.6954 | ... M7: ='Expense Build'!M6 -> 1759.5892
A9: Gross Profit
A10: Gross Profit | B10: =B2-B7 -> 462.698 | C10: =C2-C7 -> 722.742 | D10: =D2-D7 -> 658.889 | E10: =E2-E7 -> 482.062 | F10: =F2-F7 -> 972.91866 | G10: =G2-G7 -> 881.57078 | H10: =H2-H7 -> 855.79417 | I10: =I2-I7 -> 865.43426 | ... M10: =M2-M7 -> 1124.0968
A11: Gross Margin % | B11: =B10/B2 -> 0.59930937 | C11: =C10/C2 -> 0.49828262 | D11: =D10/D2 -> 0.39307253 | E11: =E10/E2 -> 0.38981249 | F11: =F10/F2 -> 0.38981249 | G11: =G10/G2 -> 0.38981249 | H11: =H10/H2 -> 0.38981249 | I11: =I10/I2 -> 0.38981249 | ... M11: =M10/M2 -> 0.38981249
A13: Opex
A14: Compensation Expenses | B14: ='Expense Build'!B9 -> 212.961 | C14: ='Expense Build'!C9 -> 296.055 | D14: ='Expense Build'!D9 -> 263.41 | E14: ='Expense Build'!E9 -> 579.012 | F14: ='Expense Build'!F9 -> 475.83633 | G14: ='Expense Build'!G9 -> 431.15979 | H14: ='Expense Build'!H9 -> 418.55293 | I14: ='Expense Build'!I9 -> 423.26772 | ... M14: ='Expense Build'!M9 -> 549.77475
A15: G&A Expenses | B15: ='Expense Build'!B10 -> 82.272 | C15: ='Expense Build'!C10 -> 100.128 | D15: ='Expense Build'!D10 -> 137.283 | E15: ='Expense Build'!E10 -> 73.824 | F15: ='Expense Build'!F10 -> 149.7518 | G15: ='Expense Build'!G10 -> 135.69151 | H15: ='Expense Build'!H10 -> 131.72398 | I15: ='Expense Build'!I10 -> 133.20778 | ... M15: ='Expense Build'!M10 -> 173.02116
A16: Depreciation & Amortization | B16: ='Expense Build'!B11 -> 13.277 | C16: ='Expense Build'!C11 -> 34.887 | D16: ='Expense Build'!D11 -> 50.854 | E16: ='Expense Build'!E11 -> 28.089 | F16: ='Expense Build'!F11 -> 56.40651 | G16: ='Expense Build'!G11 -> 51.110471 | H16: ='Expense Build'!H11 -> 49.616031 | I16: ='Expense Build'!I11 -> 50.17493 | ... M16: ='Expense Build'!M11 -> 65.171305
A17: IT Infrastructure Costs | B17: ='Expense Build'!B12 -> 11.835 | C17: ='Expense Build'!C12 -> 20.722 | D17: ='Expense Build'!D12 -> 27.109 | E17: ='Expense Build'!E12 -> 16.432 | F17: ='Expense Build'!F12 -> 33.170023 | G17: ='Expense Build'!G12 -> 30.055671 | H17: ='Expense Build'!H12 -> 29.176861 | I17: ='Expense Build'!I12 -> 29.505523 | ... M17: ='Expense Build'!M12 -> 38.324188
A18: Marketing Expenses | B18: ='Expense Build'!B13 -> 78.839 | C18: ='Expense Build'!C13 -> 36.544 | D18: ='Expense Build'!D13 -> 17.326 | E18: ='Expense Build'!E13 -> 11.77 | F18: ='Expense Build'!F13 -> 24.958633 | G18: ='Expense Build'!G13 -> 22.615252 | H18: ='Expense Build'!H13 -> 21.953996 | I18: ='Expense Build'!I13 -> 22.201296 | ... M18: ='Expense Build'!M13 -> 28.836861
A19: Digital Assets (Gains) / Losses | B19: ='Expense Build'!B14 -> 57.436 | C19: ='Expense Build'!C14 -> -13.488 | D19: ='Expense Build'!D14 -> -4.251 | E19: ='Expense Build'!E14 -> 5.577 | F19: ='Expense Build'!F14 -> 11.3185 | G19: ='Expense Build'!G14 -> 11.3185 | H19: ='Expense Build'!H14 -> 11.3185 | I19: ='Expense Build'!I14 -> 11.3185 | ... M19: ='Expense Build'!M14 -> 11.3185
A20: Gain on Sale of Intangible Assets | B20: ='Expense Build'!B15 -> 0 | C20: ='Expense Build'!C15 -> -21.634 | D20: ='Expense Build'!D15 -> 0 | E20: ='Expense Build'!E15 -> 0 | F20: ='Expense Build'!F15 -> 0 | G20: ='Expense Build'!G15 -> 0 | H20: ='Expense Build'!H15 -> 0 | I20: ='Expense Build'!I15 -> 0 | ... M20: ='Expense Build'!M15 -> 0
A21: Merger Termination Expenses | B21: ='Expense Build'!B16 -> 44.194 | C21: ='Expense Build'!C16 -> 0 | D21: ='Expense Build'!D16 -> 0 | E21: ='Expense Build'!E16 -> 0 | F21: ='Expense Build'!F16 -> 0 | G21: ='Expense Build'!G16 -> 0 | H21: ='Expense Build'!H16 -> 0 | I21: ='Expense Build'!I16 -> 0 | ... M21: ='Expense Build'!M16 -> 0
A22: Total Operating Expenses | B22: ='Expense Build'!B18 -> 500.814 | C22: ='Expense Build'!C18 -> 453.214 | D22: ='Expense Build'!D18 -> 491.731 | E22: ='Expense Build'!E18 -> 714.704 | F22: ='Expense Build'!F18 -> 751.44179 | G22: ='Expense Build'!G18 -> 681.9512 | H22: ='Expense Build'!H18 -> 662.3423 | I22: ='Expense Build'!I18 -> 669.67575 | ... M22: ='Expense Build'!M18 -> 866.44677
A24: Operating Income (EBIT)
A25: Implied EBIT | B25: =B10-B22 -> -38.116 | C25: =C10-C22 -> 269.528 | D25: =D10-D22 -> 167.158 | E25: =E10-E22 -> -232.642 | F25: =F10-F22 -> 221.47687 | G25: =G10-G22 -> 199.61958 | H25: =H10-H22 -> 193.45188 | I25: =I10-I22 -> 195.75851 | ... M25: =M10-M22 -> 257.65007
A26: EBIT | B26: =-38116/1000 -> -38.116 | C26: =269528/1000 -> 269.528 | D26: =167158/1000 -> 167.158 | E26: =-232642/1000 -> -232.642 | F26: =F10-F22 -> 221.47687 | G26: =G10-G22 -> 199.61958 | H26: =H10-H22 -> 193.45188 | I26: =I10-I22 -> 195.75851 | J26: =J10-J22 -> 197.13665 | K26: =K10-K22 -> 210.02118 | L26: =L10-L22 -> 228.18418 | M26: =M10-M22 -> 257.65007
A27: EBIT Margin % | B27: =B25/B2 -> -0.049369732 | C27: =C25/C2 -> 0.18582166 | D27: =D25/D2 -> 0.099721223 | E27: =E25/E2 -> -0.1881226 | F27: =F25/F2 -> 0.088737582 | G27: =G25/G2 -> 0.088267677 | H27: =H25/H2 -> 0.088116932 | I27: =I25/I2 -> 0.08817436 | ... M27: =M25/M2 -> 0.089347474
A29: Non-Operating
A30: True Interest Income | B30: =AVERAGE((D30/D33),(E30/E33))*B33 -> -183.11498 | C30: =AVERAGE((D30/D33),(E30/E33))*C33 -> 12.562206 | D30: =(33626/1000) -> 33.626 | E30: =17917/1000 -> 17.917 | F30: =E30*2 -> 35.834 | G30: =F30 -> 35.834 | H30: =G30 -> 35.834 | I30: =H30 -> 35.834 | J30: =I30 -> 35.834 | K30: =J30 -> 35.834 | L30: =K30 -> 35.834 | M30: =L30 -> 35.834
A31: Interest Expense | B31: =AVERAGE((D31/D33),(E31/E33))*B33 -> 11.756221 | C31: =AVERAGE((D31/D33),(E31/E33))*C33 -> -0.80651005 | D31: =-2002/1000 -> -2.002 | E31: =-679/1000 -> -0.679 | F31: =E31*2 -> -1.358 | G31: =F31 -> -1.358 | H31: =G31 -> -1.358 | I31: =H31 -> -1.358 | J31: =I31 -> -1.358 | K31: =J31 -> -1.358 | L31: =K31 -> -1.358 | M31: =L31 -> -1.358
A32: Other Non-Operating Gains/(Losses) | B32: =AVERAGE((D32/D33),(E32/E33))*B33 -> -549.03424 | C32: =AVERAGE((D32/D33),(E32/E33))*C33 -> 37.665304 | D32: =D33-(D30+D31) -> 22.792 | E32: =E33-(E30+E31) -> -180.762 | F32: =E32/2 -> -90.381 | G32: =F32 -> -90.381 | H32: =G32 -> -90.381 | I32: =H32 -> -90.381 | J32: =I32 -> -90.381 | K32: =J32 -> -90.381 | L32: =K32 -> -90.381 | M32: =L32 -> -90.381
A33: Total Other Non-Operating (Expense)/Income | B33: =-720393/1000 -> -720.393 | C33: =49421/1000 -> 49.421 | D33: =54416/1000 -> 54.416 | E33: =-163524/1000 -> -163.524 | F33: =F30+F31+F32 -> -55.905 | G33: =F33 -> -55.905 | H33: =G33 -> -55.905 | I33: =H33 -> -55.905 | J33: =I33 -> -55.905 | K33: =J33 -> -55.905 | L33: =K33 -> -55.905 | M33: =L33 -> -55.905
A35: Pre-Tax Income
A36: Implied EBT | B36: =B26+B33 -> -758.509 | C36: =C26+C33 -> 318.949 | D36: =D26+D33 -> 221.574 | E36: =E26+E33 -> -396.166 | F36: =F25+F33 -> 165.57187 | G36: =G25+G33 -> 143.71458 | H36: =H25+H33 -> 137.54688 | I36: =I25+I33 -> 139.85351 | J36: =J25+J33 -> 141.23165 | K36: =K25+K33 -> 154.11618 | L36: =L25+L33 -> 172.27918 | M36: =M25+M33 -> 201.74507
A37: EBT | B37: =-758509/1000 -> -758.509 | C37: =318949/1000 -> 318.949 | D37: =221574/1000 -> 221.574 | E37: =-396166/1000 -> -396.166 | F37: =F26+F33 -> 165.57187 | G37: =G26+G33 -> 143.71458 | H37: =H26+H33 -> 137.54688 | I37: =I26+I33 -> 139.85351 | J37: =J26+J33 -> 141.23165 | K37: =K26+K33 -> 154.11618 | L37: =L26+L33 -> 172.27918 | M37: =M26+M33 -> 201.74507
A39: Taxes
A40: Income Tax Expense | B40: =3263/1000 -> 3.263 | C40: =47400/1000 -> 47.4 | D40: =64583/1000 -> 64.583 | E40: =21143/1000 -> 21.143 | F40: =E40*2 -> 42.286 | G40: =F40 -> 42.286 | H40: =G40 -> 42.286 | I40: =H40 -> 42.286 | J40: =I40 -> 42.286 | K40: =J40 -> 42.286 | L40: =K40 -> 42.286 | M40: =L40 -> 42.286
A42: NOPAT
A43: NOPAT | B43: =B26*(1-'Drivers & Assumptons'!$C$18) -> -30.11164 | C43: =C26*(1-'Drivers & Assumptons'!$C$18) -> 212.92712 | D43: =D26*(1-'Drivers & Assumptons'!$C$18) -> 132.05482 | E43: =E26*(1-'Drivers & Assumptons'!$C$18) -> -183.78718 | F43: =F26*(1-'Drivers & Assumptons'!$C$18) -> 174.96673 | G43: =G26*(1-'Drivers & Assumptons'!$C$18) -> 157.69947 | H43: =H26*(1-'Drivers & Assumptons'!$C$18) -> 152.82698 | I43: =I26*(1-'Drivers & Assumptons'!$C$18) -> 154.64922 | ... M43: =M26*(1-'Drivers & Assumptons'!$C$18) -> 203.54355
A44: Loss from Discontinued Operations | B44: =-7075/1000 -> -7.075 | C44: =-3987/1000 -> -3.987 | D44: =-1324/1000 -> -1.324 | E44: 0 | F44: =E44 -> 0 | G44: =F44 -> 0 | H44: =G44 -> 0 | I44: =H44 -> 0 | J44: =I44 -> 0 | K44: =J44 -> 0 | L44: =K44 -> 0 | M44: =L44 -> 0
A46: Net Income
A47: Implied Net Income | B47: =B37-B40+B44 -> -768.847 | C47: =C37-C40+C44 -> 267.562 | D47: =D37-D40+D44 -> 155.667 | E47: =E37-E40+E44 -> -417.309 | F47: =F36-F40 -> 123.28587 | G47: =G36-G40 -> 101.42858 | H47: =H36-H40 -> 95.260877 | I47: =I36-I40 -> 97.56751 | J47: =J36-J40 -> 98.945652 | K47: =K36-K40 -> 111.83018 | L47: =L36-L40 -> 129.99318 | M47: =M36-M40 -> 159.45907
A48: Net Income | B48: =-768847/1000 -> -768.847 | C48: =267562/1000 -> 267.562 | D48: =155667/1000 -> 155.667 | E48: =-417309/1000 -> -417.309 | F48: =F37-F40 -> 123.28587 | G48: =G37-G40 -> 101.42858 | H48: =H37-H40 -> 95.260877 | I48: =I37-I40 -> 97.56751 | J48: =J37-J40 -> 98.945652 | K48: =K37-K40 -> 111.83018 | L48: =L37-L40 -> 129.99318 | M48: =M37-M40 -> 159.45907
A49: Net Income Margin % | B49: =B48/B2 -> -0.99584873 | C49: =C48/C2 -> 0.18446623 | D49: =D48/D2 -> 0.092866053 | E49: =E48/E2 -> -0.33745091 | F49: =F48/F2 -> 0.049396083 | G49: =G48/G2 -> 0.044849635 | H49: =H48/H2 -> 0.043391134 | I49: =I48/I2 -> 0.043946763 | ... M49: =M48/M2 -> 0.055296958
...

Sheet Balance Sheet
A1: (in millions) | B1: 2023A | C1: 2024A | D1: 2025 6M Actual | E1: 2025E | F1: 2026E | G1: 2027E | H1: 2028E | I1: 2029E | J1: 2030E | K1: 2031E | L1: 2032E
A2: Assets
A3: Current Assets
A4: Cash & Cash Equivalents (including cash and cash equivalents segregated for corporate-held stablecoins) | B4: =644432/1000 -> 644.432 | C4: =1045474/1000 -> 1045.474 | D4: =1706390/1000 -> 1706.39 | E4: =SUM('Cash Flow Statement'!F56:F58) -> 1886.3126 | F4: =SUM('Cash Flow Statement'!G56:G58) -> 2003.5826 | G4: =SUM('Cash Flow Statement'!H56:H58) -> 2128.8787 | H4: =SUM('Cash Flow Statement'!I56:I58) -> 2263.526 | I4: =SUM('Cash Flow Statement'!J56:J58) -> 2408.4767 | J4: =SUM('Cash Flow Statement'!K56:K58) -> 2564.8186 | K4: =SUM('Cash Flow Statement'!L56:L58) -> 2733.8676 | L4: =SUM('Cash Flow Statement'!M56:M58) -> 2917.0033
A5: Cash & Cash Equivalents (segregated for the benefit of stablecoin holders) | B5: =24346152/1000 -> 24346.152 | C5: =43918572/1000 -> 43918.572 | D5: =61365920/1000 -> 61365.92 | E5: =D5*(1+'Drivers & Assumptons'!$C$34*0.5) -> 63820.557 | F5: =E5*(1+'Drivers & Assumptons'!$C$34) -> 68926.201 | G5: =F5*(1+'Drivers & Assumptons'!$C$34) -> 74440.297 | H5: =G5*(1+'Drivers & Assumptons'!$C$34) -> 80395.521 | I5: =H5*(1+'Drivers & Assumptons'!$C$34) -> 86827.163 | J5: =I5*(1+'Drivers & Assumptons'!$C$34) -> 93773.336 | K5: =J5*(1+'Drivers & Assumptons'!$C$34) -> 101275.2 | L5: =K5*(1+'Drivers & Assumptons'!$C$34) -> 109377.22
A6: Other/Reconciliation to Total Cash | B6: 0 | C6: 0 | D6: 0 | E6: ='Cash Flow Statement'!F60 -> 17565.491 | F6: ='Cash Flow Statement'!G60 -> 17519.525 | G6: ='Cash Flow Statement'!H60 -> 17411.405 | H6: ='Cash Flow Statement'!I60 -> 17265.616 | I6: ='Cash Flow Statement'!J60 -> 17087.956 | J6: ='Cash Flow Statement'!K60 -> 16887.242 | K6: ='Cash Flow Statement'!L60 -> 16679.093 | L6: ='Cash Flow Statement'!M60 -> 16478.574
A7: Implied Total Cash & CE from CFS | B7: =SUM(B4:B5) -> 24990.584 | C7: =SUM(C4:C5) -> 44964.046 | D7: =SUM(D4:D5) -> 63072.31 | E7: ='Cash Flow Statement'!F62 -> 83272.36 | F7: ='Cash Flow Statement'!G62 -> 88449.309 | G7: ='Cash Flow Statement'!H62 -> 93980.582 | H7: ='Cash Flow Statement'!I62 -> 99924.663 | I7: ='Cash Flow Statement'!J62 -> 106323.6 | J7: ='Cash Flow Statement'!K62 -> 113225.4 | K7: ='Cash Flow Statement'!L62 -> 120688.16 | L7: ='Cash Flow Statement'!M62 -> 128772.8
A8: Total Cash & CE | B8: =SUM(B4:B5) -> 24990.584 | C8: =SUM(C4:C5) -> 44964.046 | D8: =SUM(D4:D5) -> 63072.31 | E8: =SUM(E4:E5) -> 65706.869 | F8: =SUM(F4:F5) -> 70929.784 | G8: =SUM(G4:G5) -> 76569.176 | H8: =SUM(H4:H5) -> 82659.047 | I8: =SUM(I4:I5) -> 89235.64 | ... L8: =SUM(L4:L5) -> 112294.22
A9: Available-for-sale debt securities, at fair value | B9: =152183/1000 -> 152.183 | C9: 0 | D9: 0 | E9: 0 | F9: 0 | G9: 0 | H9: 0 | I9: 0 | J9: 0 | K9: 0 | L9: 0
A10: Accounts receivable, net | B10: =1940/1000 -> 1.94 | C10: =6418/1000 -> 6.418 | D10: =13215/1000 -> 13.215 | E10: ='P&L'!F2*'Drivers & Assumptons'!$C$35 -> 18.113599 | F10: ='P&L'!G2*'Drivers & Assumptons'!$C$35 -> 16.412903 | G10: ='P&L'!H2*'Drivers & Assumptons'!$C$35 -> 15.932999 | H10: ='P&L'!I2*'Drivers & Assumptons'!$C$35 -> 16.112476 | I10: ='P&L'!J2*'Drivers & Assumptons'!$C$35 -> 16.219708 | J10: ='P&L'!K2*'Drivers & Assumptons'!$C$35 -> 17.222242 | K10: ='P&L'!L2*'Drivers & Assumptons'!$C$35 -> 18.635489 | L10: ='P&L'!M2*'Drivers & Assumptons'!$C$35 -> 20.928203
A11: Stablecoins receivable, net | B11: =22559/1000 -> 22.559 | C11: =6957/1000 -> 6.957 | D11: 0 | E11: 0 | F11: 0 | G11: 0 | H11: 0 | I11: 0 | J11: 0 | K11: 0 | L11: 0
A12: Prepaid expenses and other current assets | B12: =146645/1000 -> 146.645 | C12: =187528/1000 -> 187.528 | D12: =216604/1000 -> 216.604 | E12: ='P&L'!F22*'Drivers & Assumptons'!$C$38 -> 252.48391 | F12: ='P&L'!G22*'Drivers & Assumptons'!$C$38 -> 229.13512 | G12: ='P&L'!H22*'Drivers & Assumptons'!$C$38 -> 222.54655 | H12: ='P&L'!I22*'Drivers & Assumptons'!$C$38 -> 225.01058 | I12: ='P&L'!J22*'Drivers & Assumptons'!$C$38 -> 226.48276 | J12: ='P&L'!K22*'Drivers & Assumptons'!$C$38 -> 240.24651 | K12: ='P&L'!L22*'Drivers & Assumptons'!$C$38 -> 259.64892 | L12: ='P&L'!M22*'Drivers & Assumptons'!$C$38 -> 291.12551
A13: Total Operating Current Assets | B13: =SUM(B10,B11,B12) -> 171.144 | C13: =SUM(C10,C11,C12) -> 200.903 | D13: =SUM(D10,D11,D12) -> 229.819 | E13: =SUM(E10,E11,E12) -> 270.59751 | F13: =SUM(F10,F11,F12) -> 245.54803 | G13: =SUM(G10,G11,G12) -> 238.47955 | H13: =SUM(H10,H11,H12) -> 241.12306 | I13: =SUM(I10,I11,I12) -> 242.70247 | ... L13: =SUM(L10,L11,L12) -> 312.05371
A14: Non-Current Assets
A15: Available-for-sale debt securities, at fair value | B15: =87940/1000 -> 87.94 | C15: 0 | D15: 0 | E15: 0 | F15: 0 | G15: 0 | H15: 0 | I15: 0 | J15: 0 | K15: 0 | L15: 0
A16: Investments | B16: =75874/1000 -> 75.874 | C16: =84114/1000 -> 84.114 | D16: =83794/1000 -> 83.794 | E16: =D16 -> 83.794 | F16: =E16 -> 83.794 | G16: =F16 -> 83.794 | H16: =G16 -> 83.794 | I16: =H16 -> 83.794 | J16: =I16 -> 83.794 | K16: =J16 -> 83.794 | L16: =K16 -> 83.794
A17: Fixed assets, net | B17: =2619/1000 -> 2.619 | C17: =18682/1000 -> 18.682 | D17: =23804/1000 -> 23.804 | E17: =D17*(1+'Drivers & Assumptons'!C40) -> 28.5648 | F17: =E17*(1+'Drivers & Assumptons'!$C$39) -> 29.298698 | G17: =F17*(1+'Drivers & Assumptons'!$C$39) -> 30.051451 | H17: =G17*(1+'Drivers & Assumptons'!$C$39) -> 30.823544 | I17: =H17*(1+'Drivers & Assumptons'!$C$39) -> 31.615474 | J17: =I17*(1+'Drivers & Assumptons'!$C$39) -> 32.427751 | K17: =J17*(1+'Drivers & Assumptons'!$C$39) -> 33.260897 | L17: =K17*(1+'Drivers & Assumptons'!$C$39) -> 34.115449
A18: Digital assets | B18: =11339/1000 -> 11.339 | C18: =31330/1000 -> 31.33 | D18: =35113/1000 -> 35.113 | E18: =D18 -> 35.113 | F18: =E18 -> 35.113 | G18: =F18 -> 35.113 | H18: =G18 -> 35.113 | I18: =H18 -> 35.113 | J18: =I18 -> 35.113 | K18: =J18 -> 35.113 | L18: =K18 -> 35.113
A19: Goodwill | B19: 0 | C19: =169544/1000 -> 169.544 | D19: =266384/1000 -> 266.384 | E19: =D19 -> 266.384 | F19: =E19 -> 266.384 | G19: =F19 -> 266.384 | H19: =G19 -> 266.384 | I19: =H19 -> 266.384 | J19: =I19 -> 266.384 | K19: =J19 -> 266.384 | L19: =K19 -> 266.384
A20: Intangible Assets, net | B20: 0 | C20: =331394/1000 -> 331.394 | D20: =396969/1000 -> 396.969 | E20: =D20 -> 396.969 | F20: =E20 -> 396.969 | G20: =F20 -> 396.969 | H20: =G20 -> 396.969 | I20: =H20 -> 396.969 | J20: =I20 -> 396.969 | K20: =J20 -> 396.969 | L20: =K20 -> 396.969
A21: Deferred tax assets, net | B21: 0 | C21: =10223/1000 -> 10.223 | D21: 0 | E21: 0 | F21: 0 | G21: 0 | H21: 0 | I21: 0 | J21: 0 | K21: 0 | L21: 0
A22: Other non-current assets | B22: =4400/1000 -> 4.4 | C22: =20615/1000 -> 20.615 | D22: 0 | E22: 0 | F22: 0 | G22: 0 | H22: 0 | I22: 0 | J22: 0 | K22: 0 | L22: 0
A23: Other Assets/ Rounding Adjustment Plug | B23: =B42-SUM(B15:B22,B8:B12) -> -629.903 | C23: =C42-SUM(C15:C22,C8:C12) -> 15.357 | D23: =D42-SUM(D15:D22,D8:D12) -> -9.632 | E23: =E42-SUM(E15:E22,E8:E12) -> -129.61867 | F23: =F42-SUM(F15:F22,F8:F12) -> -218.09659 | G23: =G42-SUM(G15:G22,G8:G12) -> -523.5652 | H23: =H42-SUM(H15:H22,H8:H12) -> -586.89345 | I23: =I42-SUM(I15:I22,I8:I12) -> -661.2927 | ... L23: =L42-SUM(L15:L22,L8:L12) -> -863.42298
A24: Total Assets | B24: =SUM(B15:B23,B8:B12) -> 24866.18 | C24: =SUM(C15:C23,C8:C12) -> 45846.208 | D24: =SUM(D15:D23,D8:D12) -> 64098.561 | E24: =SUM(E15:E23,E8:E12) -> 66658.673 | F24: =SUM(F15:F23,F8:F12) -> 71768.794 | G24: =SUM(G15:G23,G8:G12) -> 77096.402 | H24: =SUM(H15:H23,H8:H12) -> 83126.36 | I24: =SUM(I15:I23,I8:I12) -> 89630.925 | ... L24: =SUM(L15:L23,L8:L12) -> 112559.23
A26: Liabilities, Redeemable Convertible Preferred Stock and Stockholders' Equity
A27: Current Liabilities
A28: Deferred Revenue | B28: =2499/1000 -> 2.499 | C28: =13390/1000 -> 13.39 | D28: =8507/1000 -> 8.507 | E28: =D28 -> 8.507 | F28: ='P&L'!G2*'Drivers & Assumptons'!$C$42 -> 12.506243 | G28: ='P&L'!H2*'Drivers & Assumptons'!$C$42 -> 12.140568 | H28: ='P&L'!I2*'Drivers & Assumptons'!$C$42 -> 12.277326 | I28: ='P&L'!J2*'Drivers & Assumptons'!$C$42 -> 12.359034 | J28: ='P&L'!K2*'Drivers & Assumptons'!$C$42 -> 13.122941 | K28: ='P&L'!L2*'Drivers & Assumptons'!$C$42 -> 14.199801 | L28: ='P&L'!M2*'Drivers & Assumptons'!$C$42 -> 15.946795
A29: Accounts payable and accrued expenses | B29: =152586/1000 -> 152.586 | C29: =287007/1000 -> 287.007 | D29: =411560/1000 -> 411.56 | E29: ='P&L'!F22*'Drivers & Assumptons'!$C$37 -> 374.76628 | F29: =0.5*('P&L'!G22*'Drivers & Assumptons'!C37)+0.5*(('P&L'!G22-'P&L'!G16-'Cash Flow Statement'!G17)*'Drivers & Assumptons'!C37) -> 295.8127 | G29: =('P&L'!H22-'Cash Flow Statement'!H17-'P&L'!H16)*'Drivers & Assumptons'!$C$37 -> 244.32702 | H29: =('P&L'!I22-'Cash Flow Statement'!I17-'P&L'!I16)*'Drivers & Assumptons'!$C$37 -> 247.01565 | I29: =('P&L'!J22-'Cash Flow Statement'!J17-'P&L'!J16)*'Drivers & Assumptons'!$C$37 -> 248.62202 | J29: =('P&L'!K22-'Cash Flow Statement'!K17-'P&L'!K16)*'Drivers & Assumptons'!$C$37 -> 263.64034 | K29: =('P&L'!L22-'Cash Flow Statement'!L17-'P&L'!L16)*'Drivers & Assumptons'!$C$37 -> 284.81129 | L29: =('P&L'!M22-'Cash Flow Statement'!M17-'P&L'!M16)*'Drivers & Assumptons'!$C$37 -> 319.15699
A30: Obligations to return digital asset collateral | B30: =4662/1000 -> 4.662 | C30: =570/1000 -> 0.57 | D30: 0 | E30: 0 | F30: 0 | G30: 0 | H30: 0 | I30: 0 | J30: 0 | K30: 0 | L30: 0
A31: Deposits from stablecoin holders | B31: =24276065/1000 -> 24276.065 | C31: =43727363/1000 -> 43727.363 | D31: =61101523/1000 -> 61101.523 | E31: =D31*(1+'Drivers & Assumptons'!$C$5*0.5) -> 63545.584 | F31: =E31*(1+'Drivers & Assumptons'!$C$5) -> 68629.231 | G31: =F31*(1+'Drivers & Assumptons'!$C$5) -> 74119.569 | H31: =G31*(1+'Drivers & Assumptons'!$C$5) -> 80049.135 | I31: =H31*(1+'Drivers & Assumptons'!$C$5) -> 86453.065 | J31: =I31*(1+'Drivers & Assumptons'!$C$5) -> 93369.311 | K31: =J31*(1+'Drivers & Assumptons'!$C$5) -> 100838.86 | L31: =K31*(1+'Drivers & Assumptons'!$C$5) -> 108905.96
A32: Convertible debt, net of debt discount | B32: 0 | C32: 0 | D32: =206140/1000 -> 206.14 | E32: =D32 -> 206.14 | F32: =E32 -> 206.14 | G32: 0 | H32: 0 | I32: 0 | J32: 0 | K32: 0 | L32: 0
A33: Other current liabilities | B33: =4225/1000 -> 4.225 | C33: =16027/1000 -> 16.027 | D33: 0 | E33: 0 | F33: 0 | G33: 0 | H33: 0 | I33: 0 | J33: 0 | K33: 0 | L33: 0
A34: Total Operating Current Liabilities | B34: =SUM(B28,B29,B33) -> 159.31 | C34: =SUM(C28,C29,C33) -> 316.424 | D34: =SUM(D28,D29,D33) -> 420.067 | E34: =SUM(E28,E29,E33) -> 383.27328 | F34: =SUM(F28,F29,F33) -> 308.31895 | G34: =SUM(G28,G29,G33) -> 256.46759 | H34: =SUM(H28,H29,H33) -> 259.29298 | I34: =SUM(I28,I29,I33) -> 260.98106 | ... L34: =SUM(L28,L29,L33) -> 335.10379
A35: Non-Current Liabilities
A36: Convertible debt, net of debt discount | B36: =58487/1000 -> 58.487 | C36: =40717/1000 -> 40.717 | D36: 0 | E36: 0 | F36: 0 | G36: 0 | H36: 0 | I36: 0 | J36: 0 | K36: 0 | L36: 0
A37: Deferred tax liabilities, net | B37: =19616/1000 -> 19.616 | C37: =29559/1000 -> 29.559 | D37: 0 | E37: =C37 -> 29.559 | F37: =E37 -> 29.559 | G37: =F37 -> 29.559 | H37: =G37 -> 29.559 | I37: =H37 -> 29.559 | J37: =I37 -> 29.559 | K37: =J37 -> 29.559 | L37: =K37 -> 29.559
A38: Other non-current liabilities | B38: =8569/1000 -> 8.569 | C38: =21281/1000 -> 21.281 | D38: 0 | E38: 0 | F38: 0 | G38: 0 | H38: 0 | I38: 0 | J38: 0 | K38: 0 | L38: 0
A39: Redeemable convertible preferred stock | B39: 0 | C39: =1139765/1000 -> 1139.765 | D39: 0 | E39: 0 | F39: 0 | G39: 0 | H39: 0 | I39: 0 | J39: 0 | K39: 0 | L39: 0
A40: Stockholders' Equity
A41: Total stockholders' equity | B41: =339471/1000 -> 339.471 | C41: =570529/1000 -> 570.529 | D41: =2370831/1000 -> 2370.831 | E41: =D41+'P&L'!F48 -> 2494.1169 | F41: =E41+'P&L'!G48 -> 2595.5455 | G41: =F41+'P&L'!H48 -> 2690.8063 | H41: =G41+'P&L'!I48 -> 2788.3738 | I41: =H41+'P&L'!J48 -> 2887.3195 | J41: =I41+'P&L'!K48 -> 2999.1497 | K41: =J41+'P&L'!L48 -> 3129.1428 | L41: =K41+'P&L'!M48 -> 3288.6019
...

Sheet Cash Flow Statement
A1: (in millions) | B1: 2022A | C1: 2023A | D1: 2024A | E1: 2025 6M Actual | F1: 2025E | G1: 2026E | H1: 2027E | I1: 2028E | J1: 2029E | K1: 2030E | L1: 2031E | M1: 2032E
A2: Cash flows from operating activities
A3: Net income (loss) | B3: ='P&L'!B48 -> -768.847 | C3: ='P&L'!C48 -> 267.562 | D3: ='P&L'!D48 -> 155.667 | E3: ='P&L'!E48 -> -417.309 | F3: ='P&L'!F48 -> 123.28587 | G3: ='P&L'!G48 -> 101.42858 | H3: ='P&L'!H48 -> 95.260877 | I3: ='P&L'!I48 -> 97.56751 | ... M3: ='P&L'!M48 -> 159.45907
A4: Adjustments to reconcile net income (loss) to net cash provided by (used in) operating activities:
A5: Depreciation and amortization expense | B5: =13277/1000 -> 13.277 | C5: =34887/1000 -> 34.887 | D5: =50854/1000 -> 50.854 | E5: =28089/1000 -> 28.089 | F5: ='Expense Build'!F11 -> 56.40651 | G5: ='Expense Build'!G11 -> 51.110471 | H5: ='Expense Build'!H11 -> 49.616031 | I5: ='Expense Build'!I11 -> 50.17493 | J5: ='Expense Build'!J11 -> 50.508855 | K5: ='Expense Build'!K11 -> 53.630786 | L5: ='Expense Build'!L11 -> 58.031696 | M5: ='Expense Build'!M11 -> 65.171305
A6: Accretion of premium on available-for-sale debt securities | B6: =-353422/1000 -> -353.422 | C6: =-7738/1000 -> -7.738 | D6: =-2268/1000 -> -2.268 | E6: 0 | F6: 0 | G6: 0 | H6: 0 | I6: 0 | J6: 0 | K6: 0 | L6: 0 | M6: 0
A7: Realized and unrealized (gains) losses on digital assets | B7: =269277/1000 -> 269.277 | C7: =-13010/1000 -> -13.01 | D7: =-12878/1000 -> -12.878 | E7: =7189/1000 -> 7.189 | F7: 0 | G7: 0 | H7: 0 | I7: 0 | J7: 0 | K7: 0 | L7: 0 | M7: 0
A8: Change in fair value of convertible debt, warrant liability, and embedded derivatives | B8: =486938/1000 -> 486.938 | C8: =-25343/1000 -> -25.343 | D8: =-10024/1000 -> -10.024 | E8: =170106/1000 -> 170.106 | F8: 0 | G8: 0 | H8: 0 | I8: 0 | J8: 0 | K8: 0 | L8: 0 | M8: 0
A9: Digital assets received for services | B9: =-7235/1000 -> -7.235 | C9: =-4476/1000 -> -4.476 | D9: =-1500/1000 -> -1.5 | E9: =-9416/1000 -> -9.416 | F9: 0 | G9: 0 | H9: 0 | I9: 0 | J9: 0 | K9: 0 | L9: 0 | M9: 0
A10: Equity securities received for services | B10: 0 | C10: 0 | D10: 0 | E10: =-3826/1000 -> -3.826 | F10: 0 | G10: 0 | H10: 0 | I10: 0 | J10: 0 | K10: 0 | L10: 0 | M10: 0
A11: Deferred taxes | B11: =-786/1000 -> -0.786 | C11: =-32893/1000 -> -32.893 | D11: =-2806/1000 -> -2.806 | E11: =-5751/1000 -> -5.751 | F11: 0 | G11: 0 | H11: 0 | I11: 0 | J11: 0 | K11: 0 | L11: 0 | M11: 0
A12: Realized and unrealized (gains) losses on available-for-sale debt securities and strategic investments | B12: =26877/1000 -> 26.877 | C12: =1749/1000 -> 1.749 | D12: =-434/1000 -> -0.434 | E12: =1416/1000 -> 1.416 | F12: 0 | G12: 0 | H12: 0 | I12: 0 | J12: 0 | K12: 0 | L12: 0 | M12: 0
A13: Gain on sale of long-lived assets | B13: 0 | C13: =-21521/1000 -> -21.521 | D13: 0 | E13: 0 | F13: 0 | G13: 0 | H13: 0 | I13: 0 | J13: 0 | K13: 0 | L13: 0 | M13: 0
A14: Foreign currency remeasurement | B14: 0 | C14: 0 | D14: 0 | E14: =8763/1000 -> 8.763 | F14: 0 | G14: 0 | H14: 0 | I14: 0 | J14: 0 | K14: 0 | L14: 0 | M14: 0
A15: Provisions for warrants in common stock | B15: 0 | C15: 0 | D15: 0 | E15: =5565/1000 -> 5.565 | F15: 0 | G15: 0 | H15: 0 | I15: 0 | J15: 0 | K15: 0 | L15: 0 | M15: 0
A16: Shares issued for merger-termination | B16: =15520/1000 -> 15.52 | C16: 0 | D16: 0 | E16: 0 | F16: 0 | G16: 0 | H16: 0 | I16: 0 | J16: 0 | K16: 0 | L16: 0 | M16: 0
A17: Stock-based compensation | B17: =69266/1000 -> 69.266 | C17: =107999/1000 -> 107.999 | D17: =50134/1000 -> 50.134 | E17: =447682/1000 -> 447.682 | F17: =E17*2 -> 895.364 | G17: ='Expense Build'!G9*'Drivers & Assumptons'!$C$44 -> 126.52709 | H17: ='Expense Build'!H9*'Drivers & Assumptons'!$C$44 -> 122.82751 | I17: ='Expense Build'!I9*'Drivers & Assumptons'!$C$44 -> 124.2111 | J17: ='Expense Build'!J9*'Drivers & Assumptons'!$C$44 -> 125.03775 | K17: ='Expense Build'!K9*'Drivers & Assumptons'!$C$44 -> 132.76628 | L17: ='Expense Build'!L9*'Drivers & Assumptons'!$C$44 -> 143.66101 | M17: ='Expense Build'!M9*'Drivers & Assumptons'!$C$44 -> 161.33554
A18: Other non-cash items | B18: =5547/1000 -> 5.547 | C18: =4811/1000 -> 4.811 | D18: 0 | E18: =2306/1000 -> 2.306 | F18: =E18 -> 2.306 | G18: =F18 -> 2.306 | H18: =G18 -> 2.306 | I18: =H18 -> 2.306 | J18: =I18 -> 2.306 | K18: =J18 -> 2.306 | L18: =K18 -> 2.306 | M18: =L18 -> 2.306
A19: Changes in operating assets and liabilities:
A20: Accounts receivable | B20: =18735/1000 -> 18.735 | C20: =2244/1000 -> 2.244 | D20: =-4569/1000 -> -4.569 | E20: =-8635/1000 -> -8.635 | F20: =-('Balance Sheet'!E10-'Balance Sheet'!C10) -> -11.695599 | G20: =-('Balance Sheet'!F10-'Balance Sheet'!E10) -> 1.700696 | H20: =-('Balance Sheet'!G10-'Balance Sheet'!F10) -> 0.47990348 | I20: =-('Balance Sheet'!H10-'Balance Sheet'!G10) -> -0.17947706 | J20: =-('Balance Sheet'!I10-'Balance Sheet'!H10) -> -0.107232 | K20: =-('Balance Sheet'!J10-'Balance Sheet'!I10) -> -1.0025332 | L20: =-('Balance Sheet'!K10-'Balance Sheet'!J10) -> -1.413247 | M20: =-('Balance Sheet'!L10-'Balance Sheet'!K10) -> -2.2927143
A21: Prepaid expenses and other current assets | B21: =-77571/1000 -> -77.571 | C21: =-51161/1000 -> -51.161 | D21: =-21764/1000 -> -21.764 | E21: =-42104/1000 -> -42.104 | F21: =-('Balance Sheet'!E12-'Balance Sheet'!C12) -> -64.955915 | G21: =-('Balance Sheet'!F12-'Balance Sheet'!E12) -> 23.348791 | H21: =('Balance Sheet'!G12-'Balance Sheet'!F12)*-1 -> 6.5885765 | I21: =('Balance Sheet'!H12-'Balance Sheet'!G12)*-1 -> -2.4640337 | J21: =('Balance Sheet'!I12-'Balance Sheet'!H12)*-1 -> -1.472184 | K21: =('Balance Sheet'!J12-'Balance Sheet'!I12)*-1 -> -13.763741 | L21: =('Balance Sheet'!K12-'Balance Sheet'!J12)*-1 -> -19.402414 | M21: =('Balance Sheet'!L12-'Balance Sheet'!K12)*-1 -> -31.476587
A22: Accounts payable and accrued expenses | B22: =227300/1000 -> 227.3 | C22: =-123833/1000 -> -123.833 | D22: =132878/1000 -> 132.878 | E22: =123981/1000 -> 123.981 | F22: ='Balance Sheet'!E29-'Balance Sheet'!C29 -> 87.759277 | G22: =('Expense Build'!G9-'Cash Flow Statement'!G17-'Cash Flow Statement'!G5)*'Drivers & Assumptons'!$C$37 -> 126.43904 | H22: =('Expense Build'!H9-'Cash Flow Statement'!H17-'Cash Flow Statement'!H5)*'Drivers & Assumptons'!$C$37 -> 122.74204 | I22: =('Expense Build'!I9-'Cash Flow Statement'!I17-'Cash Flow Statement'!I5)*'Drivers & Assumptons'!$C$37 -> 124.12467 | J22: =('Expense Build'!J9-'Cash Flow Statement'!J17-'Cash Flow Statement'!J5)*'Drivers & Assumptons'!$C$37 -> 124.95074 | K22: =('Expense Build'!K9-'Cash Flow Statement'!K17-'Cash Flow Statement'!K5)*'Drivers & Assumptons'!$C$37 -> 132.6739 | L22: =('Expense Build'!L9-'Cash Flow Statement'!L17-'Cash Flow Statement'!L5)*'Drivers & Assumptons'!$C$37 -> 143.56104 | M22: =('Expense Build'!M9-'Cash Flow Statement'!M17-'Cash Flow Statement'!M5)*'Drivers & Assumptons'!$C$37 -> 161.22328
A23: Other current liabilities | B23: =2431/1000 -> 2.431 | C23: =291/1000 -> 0.291 | D23: =10891/1000 -> 10.891 | E23: =-4340/1000 -> -4.34 | F23: ='Balance Sheet'!E33-'Balance Sheet'!C33 -> -16.027 | G23: ='Balance Sheet'!F33-'Balance Sheet'!E33 -> 0 | H23: ='Balance Sheet'!G33-'Balance Sheet'!F33 -> 0 | I23: ='Balance Sheet'!H33-'Balance Sheet'!G33 -> 0 | J23: ='Balance Sheet'!I33-'Balance Sheet'!H33 -> 0 | K23: ='Balance Sheet'!J33-'Balance Sheet'!I33 -> 0 | L23: ='Balance Sheet'!K33-'Balance Sheet'!J33 -> 0 | M23: ='Balance Sheet'!L33-'Balance Sheet'!K33 -> 0
A24: Net cash provided by (used in) operating activities | B24: =SUM(B3:B23) -> -72.693 | C24: =SUM(C3:C23) -> 139.568 | D24: =SUM(D3:D23) -> 344.181 | E24: =SUM(E3:E23) -> 303.716 | F24: =SUM(F3:F23) -> 1072.4431 | G24: =SUM(G3:G23) -> 432.86067 | H24: =SUM(H3:H23) -> 399.82094 | I24: =SUM(I3:I23) -> 395.7407 | ... M24: =SUM(M3:M23) -> 515.72589
A26: Cash flows from investing activities
A27: Proceeds from sale of discontinued business | B27: =1000/1000 -> 1 | C27: 0 | D27: 0 | E27: 0 | F27: 0 | G27: 0 | H27: 0 | I27: 0 | J27: 0 | K27: 0 | L27: 0 | M27: 0
A28: Purchase of available-for-sale debt securities | B28: =-102850973/1000 -> -102850.97 | C28: =-311639/1000 -> -311.639 | D28: =-99313/1000 -> -99.313 | E28: 0 | F28: =-('Balance Sheet'!E31-'Balance Sheet'!C31) -> -19818.221 | G28: =-('Balance Sheet'!F31-'Balance Sheet'!E31) -> -5083.6467 | H28: =-('Balance Sheet'!G31-'Balance Sheet'!F31) -> -5490.3385 | I28: =-('Balance Sheet'!H31-'Balance Sheet'!G31) -> -5929.5655 | J28: =-('Balance Sheet'!I31-'Balance Sheet'!H31) -> -6403.9308 | K28: =-('Balance Sheet'!J31-'Balance Sheet'!I31) -> -6916.2452 | L28: =-('Balance Sheet'!K31-'Balance Sheet'!J31) -> -7469.5448 | M28: =-('Balance Sheet'!L31-'Balance Sheet'!K31) -> -8067.1084
A29: Sales and maturities of available-for-sale debt securities | B29: =94442236/1000 -> 94442.236 | C29: =8827550/1000 -> 8827.55 | D29: =341561/1000 -> 341.561 | E29: 0 | F29: ='Drivers & Assumptons'!$C$45*ABS(F28) -> 18827.31 | G29: ='Drivers & Assumptons'!$C$45*ABS(G28) -> 4829.4644 | H29: ='Drivers & Assumptons'!$C$45*ABS(H28) -> 5215.8215 | I29: ='Drivers & Assumptons'!$C$45*ABS(I28) -> 5633.0873 | J29: ='Drivers & Assumptons'!$C$45*ABS(J28) -> 6083.7342 | K29: ='Drivers & Assumptons'!$C$45*ABS(K28) -> 6570.433 | L29: ='Drivers & Assumptons'!$C$45*ABS(L28) -> 7096.0676 | M29: ='Drivers & Assumptons'!$C$45*ABS(M28) -> 7663.753
A30: Cash acquired from acquisition of equity method affiliate | B30: 0 | C30: =1629/1000 -> 1.629 | D30: 0 | E30: 0 | F30: 0 | G30: 0 | H30: 0 | I30: 0 | J30: 0 | K30: 0 | L30: 0 | M30: 0
A31: Sale and return of investments | B31: 0 | C31: =1107/1000 -> 1.107 | D31: =739/1000 -> 0.739 | E31: =194/1000 -> 0.194 | F31: 0 | G31: 0 | H31: 0 | I31: 0 | J31: 0 | K31: 0 | L31: 0 | M31: 0
A32: Purchase of investments | B32: =-16032/1000 -> -16.032 | C32: =-2661/1000 -> -2.661 | D32: =-4265/1000 -> -4.265 | E32: =-6370/1000 -> -6.37 | F32: 0 | G32: 0 | H32: 0 | I32: 0 | J32: 0 | K32: 0 | L32: 0 | M32: 0
A33: Business combinations, net of cash acquired | B33: =-43456/1000 -> -43.456 | C33: 0 | D33: 0 | E33: =-7734/1000 -> -7.734 | F33: 0 | G33: 0 | H33: 0 | I33: 0 | J33: 0 | K33: 0 | L33: 0 | M33: 0
A34: Proceeds from the sale of digital assets | B34: 0 | C34: =27301/1000 -> 27.301 | D34: =4805/1000 -> 4.805 | E34: =79/1000 -> 0.079 | F34: 0 | G34: 0 | H34: 0 | I34: 0 | J34: 0 | K34: 0 | L34: 0 | M34: 0
A35: Capitalization of software development costs | B35: =-18315/1000 -> -18.315 | C35: =-32862/1000 -> -32.862 | D35: =-39098/1000 -> -39.098 | E35: =-24858/1000 -> -24.858 | F35: =E35*2 -> -49.716 | G35: =F35 -> -49.716 | H35: =G35 -> -49.716 | I35: =H35 -> -49.716 | J35: =I35 -> -49.716 | K35: =J35 -> -49.716 | L35: =K35 -> -49.716 | M35: =L35 -> -49.716
A36: Purchase of long-lived assets | B36: =-3050/1000 -> -3.05 | C36: =-654/1000 -> -0.654 | D36: =-18128/1000 -> -18.128 | E36: =-7419/1000 -> -7.419 | F36: =2*E36 -> -14.838 | G36: =F36 -> -14.838 | H36: =G36 -> -14.838 | I36: =H36 -> -14.838 | J36: =I36 -> -14.838 | K36: =J36 -> -14.838 | L36: =K36 -> -14.838 | M36: =L36 -> -14.838
A37: Net cash provided by (used in) investing activities | B37: =SUM(B27:B36) -> -8488.59 | C37: =SUM(C27:C36) -> 8509.771 | D37: =SUM(D27:D36) -> 186.301 | E37: =SUM(E27:E36) -> -46.108 | F37: =SUM(F27:F36) -> -1055.465 | G37: =SUM(G27:G36) -> -318.73634 | H37: =SUM(H27:H36) -> -339.07092 | I37: =SUM(I27:I36) -> -361.03228 | ... M37: =SUM(M27:M36) -> -467.90942
A39: Cash flows from financing activities
A40: Net changes in deposits held for stablecoin holders | B40: =2176756/1000 -> 2176.756 | C40: =-20322155/1000 -> -20322.155 | D40: =19452147/1000 -> 19452.147 | E40: =17339497/1000 -> 17339.497 | F40: ='Balance Sheet'!E31-'Balance Sheet'!C31 -> 19818.221 | G40: ='Balance Sheet'!F31-'Balance Sheet'!E31 -> 5083.6467 | H40: ='Balance Sheet'!G31-'Balance Sheet'!F31 -> 5490.3385 | I40: ='Balance Sheet'!H31-'Balance Sheet'!G31 -> 5929.5655 | J40: ='Balance Sheet'!I31-'Balance Sheet'!H31 -> 6403.9308 | K40: ='Balance Sheet'!J31-'Balance Sheet'!I31 -> 6916.2452 | L40: ='Balance Sheet'!K31-'Balance Sheet'!J31 -> 7469.5448 | M40: ='Balance Sheet'!L31-'Balance Sheet'!K31 -> 8067.1084
A41: Proceeds from issuance of common stock in connection with IPO, net of underwriting discounts and commissions and offering costs | B41: 0 | C41: 0 | D41: 0 | E41: =572558/1000 -> 572.558 | F41: =E41 -> 572.558 | G41: 0 | H41: 0 | I41: 0 | J41: 0 | K41: 0 | L41: 0 | M41: 0
A42: Payment of withholding taxes on settlement of RSUs | B42: 0 | C42: 0 | D42: 0 | E42: =-121794/1000 -> -121.794 | F42: =E42*2 -> -243.588 | G42: =(F42/F17)*G17 -> -34.422292 | H42: =(G42/G17)*H17 -> -33.415804 | I42: =(H42/H17)*I17 -> -33.792216 | J42: =(I42/I17)*J17 -> -34.017111 | K42: =(J42/J17)*K17 -> -36.119694 | L42: =(K42/K17)*L17 -> -39.083655 | M42: =(L42/L17)*M17 -> -43.892096
...

Sheet Supporting Schedules
A1: Compensation Expense
A2: Year | B2: Headcount | C2: Avg Comp | D2: Compensation Expense | E2: Implied Cost Per Employee | F2: % Total Revenue
A3: 2022A | B3: 900 | C3: =D3/B3 -> 236623.33 | D3: =B3*C3 -> 0 | E3: =D3/B3 -> 236623.33 | F3: =D3/(_xlfn.XLOOKUP(A3,'P&L'!$B$1:$M$1,'P&L'!$B$2:$M$2)*1000000) -> 0.27583764
A4: 2023A | B4: 1200 | C4: =D4/B4 -> 246712.5 | D4: ='P&L'!C14*1000000 -> 296055000 | E4: =D4/B4 -> 246712.5 | F4: =D4/(_xlfn.XLOOKUP(A4,'P&L'!$B$1:$M$1,'P&L'!$B$2:$M$2)*1000000) -> 0.20411027
A5: 2024A | B5: 1100 | C5: =C4*(1+0.03) -> 254113.88 | D5: ='P&L'!D14*1000000 -> 2.6341e+08 | E5: =D5/B5 -> 239463.64 | F5: =D5/(_xlfn.XLOOKUP(A5,'P&L'!$B$1:$M$1,'P&L'!$B$2:$M$2)*1000000) -> 0.15714215
A6: 2025 6M Actual | B6: =B5 -> 1100 | C6: =C5*(1+0.03) -> 261737.29 | D6: ='P&L'!E14*1000000 -> 579012000 | E6: =D6/B6 -> 526374.55 | F6: =D6/(_xlfn.XLOOKUP(A6,'P&L'!$B$1:$M$1,'P&L'!$B$2:$M$2)*1000000) -> 0.46820971
